[2020-08-26 12:08:25,314] {taskinstance.py:669} INFO - Dependencies all met for <TaskInstance: employees_dag.mysql_to_csv 2020-08-26T06:28:33.690233+00:00 [queued]>
[2020-08-26 12:08:25,323] {taskinstance.py:669} INFO - Dependencies all met for <TaskInstance: employees_dag.mysql_to_csv 2020-08-26T06:28:33.690233+00:00 [queued]>
[2020-08-26 12:08:25,323] {taskinstance.py:879} INFO - 
--------------------------------------------------------------------------------
[2020-08-26 12:08:25,324] {taskinstance.py:880} INFO - Starting attempt 2 of 2
[2020-08-26 12:08:25,324] {taskinstance.py:881} INFO - 
--------------------------------------------------------------------------------
[2020-08-26 12:08:25,538] {taskinstance.py:900} INFO - Executing <Task(MySqlOperator): mysql_to_csv> on 2020-08-26T06:28:33.690233+00:00
[2020-08-26 12:08:25,543] {standard_task_runner.py:53} INFO - Started process 86632 to run task
[2020-08-26 12:08:25,748] {logging_mixin.py:112} INFO - Running %s on host %s <TaskInstance: employees_dag.mysql_to_csv 2020-08-26T06:28:33.690233+00:00 [running]> bhakti-Vostro-3558
[2020-08-26 12:08:25,761] {mysql_operator.py:61} INFO - Executing: SELECT * FROM employees INTO OUTFILE "/input_files_mysql/sample4.csv"
FIELDS ENCLOSED BY '"' TERMINATED BY ',' ESCAPED BY '"' LINES TERMINATED BY "\n";
[2020-08-26 12:08:25,807] {logging_mixin.py:112} INFO - [2020-08-26 12:08:25,807] {base_hook.py:87} INFO - Using connection to: id: local_mysql. Host: 127.0.0.1, Port: 3306, Schema: sqoop_db, Login: sqoop_db, Password: XXXXXXXX, extra: None
[2020-08-26 12:08:25,810] {taskinstance.py:1145} ERROR - (1045, "Access denied for user 'sqoop_db'@'172.22.0.1' (using password: YES)")
Traceback (most recent call last):
  File "/usr/local/lib/python3.8/dist-packages/airflow/models/taskinstance.py", line 983, in _run_raw_task
    result = task_copy.execute(context=context)
  File "/usr/local/lib/python3.8/dist-packages/airflow/operators/mysql_operator.py", line 64, in execute
    hook.run(
  File "/usr/local/lib/python3.8/dist-packages/airflow/hooks/dbapi_hook.py", line 162, in run
    with closing(self.get_conn()) as conn:
  File "/usr/local/lib/python3.8/dist-packages/airflow/hooks/mysql_hook.py", line 116, in get_conn
    conn = MySQLdb.connect(**conn_config)
  File "/usr/local/lib/python3.8/dist-packages/pymysql/__init__.py", line 94, in Connect
    return Connection(*args, **kwargs)
  File "/usr/local/lib/python3.8/dist-packages/pymysql/connections.py", line 325, in __init__
    self.connect()
  File "/usr/local/lib/python3.8/dist-packages/pymysql/connections.py", line 599, in connect
    self._request_authentication()
  File "/usr/local/lib/python3.8/dist-packages/pymysql/connections.py", line 861, in _request_authentication
    auth_packet = self._read_packet()
  File "/usr/local/lib/python3.8/dist-packages/pymysql/connections.py", line 684, in _read_packet
    packet.check_error()
  File "/usr/local/lib/python3.8/dist-packages/pymysql/protocol.py", line 220, in check_error
    err.raise_mysql_exception(self._data)
  File "/usr/local/lib/python3.8/dist-packages/pymysql/err.py", line 109, in raise_mysql_exception
    raise errorclass(errno, errval)
pymysql.err.OperationalError: (1045, "Access denied for user 'sqoop_db'@'172.22.0.1' (using password: YES)")
[2020-08-26 12:08:25,812] {taskinstance.py:1174} INFO - All retries failed; marking task as FAILED.dag_id=employees_dag, task_id=mysql_to_csv, execution_date=20200826T062833, start_date=20200826T063825, end_date=20200826T063825
[2020-08-26 12:08:35,163] {logging_mixin.py:112} INFO - [2020-08-26 12:08:35,162] {local_task_job.py:103} INFO - Task exited with return code 1
