[2020-08-26 11:56:07,280] {taskinstance.py:669} INFO - Dependencies all met for <TaskInstance: employees_dag.insert_mysql_table 2020-08-25T06:20:03.393737+00:00 [queued]>
[2020-08-26 11:56:07,289] {taskinstance.py:669} INFO - Dependencies all met for <TaskInstance: employees_dag.insert_mysql_table 2020-08-25T06:20:03.393737+00:00 [queued]>
[2020-08-26 11:56:07,290] {taskinstance.py:879} INFO - 
--------------------------------------------------------------------------------
[2020-08-26 11:56:07,290] {taskinstance.py:880} INFO - Starting attempt 1 of 2
[2020-08-26 11:56:07,290] {taskinstance.py:881} INFO - 
--------------------------------------------------------------------------------
[2020-08-26 11:56:07,466] {taskinstance.py:900} INFO - Executing <Task(MySqlOperator): insert_mysql_table> on 2020-08-25T06:20:03.393737+00:00
[2020-08-26 11:56:07,470] {standard_task_runner.py:53} INFO - Started process 79259 to run task
[2020-08-26 11:56:07,691] {logging_mixin.py:112} INFO - Running %s on host %s <TaskInstance: employees_dag.insert_mysql_table 2020-08-25T06:20:03.393737+00:00 [running]> bhakti-Vostro-3558
[2020-08-26 11:56:07,702] {taskinstance.py:1145} ERROR - insert_data.sql
Traceback (most recent call last):
  File "/usr/local/lib/python3.8/dist-packages/airflow/models/taskinstance.py", line 964, in _run_raw_task
    self.render_templates(context=context)
  File "/usr/local/lib/python3.8/dist-packages/airflow/models/taskinstance.py", line 1426, in render_templates
    self.task.render_template_fields(context)
  File "/usr/local/lib/python3.8/dist-packages/airflow/models/baseoperator.py", line 716, in render_template_fields
    self._do_render_template_fields(self, self.template_fields, context, jinja_env, set())
  File "/usr/local/lib/python3.8/dist-packages/airflow/models/baseoperator.py", line 723, in _do_render_template_fields
    rendered_content = self.render_template(content, context, jinja_env, seen_oids)
  File "/usr/local/lib/python3.8/dist-packages/airflow/models/baseoperator.py", line 750, in render_template
    return jinja_env.get_template(content).render(**context)
  File "/usr/local/lib/python3.8/dist-packages/jinja2/environment.py", line 830, in get_template
    return self._load_template(name, self.make_globals(globals))
  File "/usr/local/lib/python3.8/dist-packages/jinja2/environment.py", line 804, in _load_template
    template = self.loader.load(self, name, globals)
  File "/usr/local/lib/python3.8/dist-packages/jinja2/loaders.py", line 113, in load
    source, filename, uptodate = self.get_source(environment, name)
  File "/usr/local/lib/python3.8/dist-packages/jinja2/loaders.py", line 187, in get_source
    raise TemplateNotFound(template)
jinja2.exceptions.TemplateNotFound: insert_data.sql
[2020-08-26 11:56:07,705] {taskinstance.py:1168} INFO - Marking task as UP_FOR_RETRY
[2020-08-26 11:56:17,123] {logging_mixin.py:112} INFO - [2020-08-26 11:56:17,122] {local_task_job.py:103} INFO - Task exited with return code 1
