[2020-07-13 16:55:49,902] {taskinstance.py:669} INFO - Dependencies all met for <TaskInstance: employees_dag.check_file_exists 2020-07-13T11:24:50.591464+00:00 [queued]>
[2020-07-13 16:55:49,911] {taskinstance.py:669} INFO - Dependencies all met for <TaskInstance: employees_dag.check_file_exists 2020-07-13T11:24:50.591464+00:00 [queued]>
[2020-07-13 16:55:49,911] {taskinstance.py:879} INFO - 
--------------------------------------------------------------------------------
[2020-07-13 16:55:49,911] {taskinstance.py:880} INFO - Starting attempt 1 of 3
[2020-07-13 16:55:49,911] {taskinstance.py:881} INFO - 
--------------------------------------------------------------------------------
[2020-07-13 16:55:50,043] {taskinstance.py:900} INFO - Executing <Task(BashOperator): check_file_exists> on 2020-07-13T11:24:50.591464+00:00
[2020-07-13 16:55:50,048] {standard_task_runner.py:53} INFO - Started process 29830 to run task
[2020-07-13 16:55:50,210] {logging_mixin.py:112} INFO - Running %s on host %s <TaskInstance: employees_dag.check_file_exists 2020-07-13T11:24:50.591464+00:00 [running]> bhakti-Vostro-3558
[2020-07-13 16:55:50,224] {bash_operator.py:82} INFO - Tmp dir root location: 
 /tmp
[2020-07-13 16:55:50,241] {bash_operator.py:103} INFO - Temporary script location: /tmp/airflowtmpc0ba4j5x/check_file_existsxaknxrwh
[2020-07-13 16:55:50,242] {bash_operator.py:115} INFO - Running command: shasum ~/home/bhakti/airflow/input_data/sample.csv
[2020-07-13 16:55:50,252] {bash_operator.py:122} INFO - Output:
[2020-07-13 16:55:51,080] {bash_operator.py:126} INFO - shasum: /home/bhakti/home/bhakti/airflow/input_data/sample.csv: No such file or directory
[2020-07-13 16:55:51,081] {bash_operator.py:128} INFO - Command exited with return code 1
[2020-07-13 16:55:51,088] {taskinstance.py:1145} ERROR - Bash command failed
Traceback (most recent call last):
  File "/usr/local/lib/python3.8/dist-packages/airflow/models/taskinstance.py", line 983, in _run_raw_task
    result = task_copy.execute(context=context)
  File "/usr/local/lib/python3.8/dist-packages/airflow/operators/bash_operator.py", line 134, in execute
    raise AirflowException("Bash command failed")
airflow.exceptions.AirflowException: Bash command failed
[2020-07-13 16:55:51,191] {taskinstance.py:1168} INFO - Marking task as UP_FOR_RETRY
[2020-07-13 16:55:59,727] {logging_mixin.py:112} INFO - [2020-07-13 16:55:59,727] {local_task_job.py:103} INFO - Task exited with return code 1
