[2020-07-18 12:29:00,051] {taskinstance.py:669} INFO - Dependencies all met for <TaskInstance: storing_data.mysql_status 2020-07-18T06:57:05.124584+00:00 [queued]>
[2020-07-18 12:29:00,061] {taskinstance.py:669} INFO - Dependencies all met for <TaskInstance: storing_data.mysql_status 2020-07-18T06:57:05.124584+00:00 [queued]>
[2020-07-18 12:29:00,062] {taskinstance.py:879} INFO - 
--------------------------------------------------------------------------------
[2020-07-18 12:29:00,062] {taskinstance.py:880} INFO - Starting attempt 2 of 2
[2020-07-18 12:29:00,062] {taskinstance.py:881} INFO - 
--------------------------------------------------------------------------------
[2020-07-18 12:29:00,229] {taskinstance.py:900} INFO - Executing <Task(BashOperator): mysql_status> on 2020-07-18T06:57:05.124584+00:00
[2020-07-18 12:29:00,234] {standard_task_runner.py:53} INFO - Started process 17202 to run task
[2020-07-18 12:29:00,415] {logging_mixin.py:112} INFO - Running %s on host %s <TaskInstance: storing_data.mysql_status 2020-07-18T06:57:05.124584+00:00 [running]> bhakti-Vostro-3558
[2020-07-18 12:29:00,435] {bash_operator.py:82} INFO - Tmp dir root location: 
 /tmp
[2020-07-18 12:29:00,436] {bash_operator.py:103} INFO - Temporary script location: /tmp/airflowtmphusybbse/mysql_status1thwukh2
[2020-07-18 12:29:00,436] {bash_operator.py:115} INFO - Running command: #!/bin/bash -x
user=root
dbname=airflow_db2
location='/home/bhakti/airflow/input_data/dump_mysql_db.db'
docker exec -it mysqlCon \
mysqldump --user $user --databases $dbname > $location
python3 '/home/bhakti/airflow/minioconnect/minio_connection.py'
[2020-07-18 12:29:00,445] {bash_operator.py:122} INFO - Output:
[2020-07-18 12:29:02,369] {bash_operator.py:126} INFO - ariflowkey
[2020-07-18 12:29:02,372] {bash_operator.py:126} INFO - [2020-07-18 12:29:02,371] {connectionpool.py:744} WARNING - Retrying ('\x1b[1mRetry(total=4, connect=None, read=None, redirect=None, status=None)\x1b[0m') after connection broken by ''\x1b[1m<urllib3.connection.HTTPConnection object at 0x7f45016423a0>: Failed to establish a new connection: [Errno 111] Connection refused\x1b[0m'': /airflowbucket?location=
[2020-07-18 12:29:02,774] {bash_operator.py:126} INFO - [2020-07-18 12:29:02,773] {connectionpool.py:744} WARNING - Retrying ('\x1b[1mRetry(total=3, connect=None, read=None, redirect=None, status=None)\x1b[0m') after connection broken by ''\x1b[1m<urllib3.connection.HTTPConnection object at 0x7f45016425b0>: Failed to establish a new connection: [Errno 111] Connection refused\x1b[0m'': /airflowbucket?location=
[2020-07-18 12:29:03,576] {bash_operator.py:126} INFO - [2020-07-18 12:29:03,575] {connectionpool.py:744} WARNING - Retrying ('\x1b[1mRetry(total=2, connect=None, read=None, redirect=None, status=None)\x1b[0m') after connection broken by ''\x1b[1m<urllib3.connection.HTTPConnection object at 0x7f4501642730>: Failed to establish a new connection: [Errno 111] Connection refused\x1b[0m'': /airflowbucket?location=
[2020-07-18 12:29:05,179] {bash_operator.py:126} INFO - [2020-07-18 12:29:05,178] {connectionpool.py:744} WARNING - Retrying ('\x1b[1mRetry(total=1, connect=None, read=None, redirect=None, status=None)\x1b[0m') after connection broken by ''\x1b[1m<urllib3.connection.HTTPConnection object at 0x7f45016428b0>: Failed to establish a new connection: [Errno 111] Connection refused\x1b[0m'': /airflowbucket?location=
[2020-07-18 12:29:08,383] {bash_operator.py:126} INFO - [2020-07-18 12:29:08,382] {connectionpool.py:744} WARNING - Retrying ('\x1b[1mRetry(total=0, connect=None, read=None, redirect=None, status=None)\x1b[0m') after connection broken by ''\x1b[1m<urllib3.connection.HTTPConnection object at 0x7f4501642a30>: Failed to establish a new connection: [Errno 111] Connection refused\x1b[0m'': /airflowbucket?location=
[2020-07-18 12:29:08,402] {bash_operator.py:126} INFO - Traceback (most recent call last):
[2020-07-18 12:29:08,402] {bash_operator.py:126} INFO -   File "/usr/lib/python3/dist-packages/urllib3/connection.py", line 156, in _new_conn
[2020-07-18 12:29:08,402] {bash_operator.py:126} INFO -     conn = connection.create_connection(
[2020-07-18 12:29:08,402] {bash_operator.py:126} INFO -   File "/usr/lib/python3/dist-packages/urllib3/util/connection.py", line 84, in create_connection
[2020-07-18 12:29:08,402] {bash_operator.py:126} INFO -     raise err
[2020-07-18 12:29:08,402] {bash_operator.py:126} INFO -   File "/usr/lib/python3/dist-packages/urllib3/util/connection.py", line 74, in create_connection
[2020-07-18 12:29:08,403] {bash_operator.py:126} INFO -     sock.connect(sa)
[2020-07-18 12:29:08,403] {bash_operator.py:126} INFO - ConnectionRefusedError: [Errno 111] Connection refused
[2020-07-18 12:29:08,403] {bash_operator.py:126} INFO - 
[2020-07-18 12:29:08,403] {bash_operator.py:126} INFO - During handling of the above exception, another exception occurred:
[2020-07-18 12:29:08,403] {bash_operator.py:126} INFO - 
[2020-07-18 12:29:08,403] {bash_operator.py:126} INFO - Traceback (most recent call last):
[2020-07-18 12:29:08,403] {bash_operator.py:126} INFO -   File "/usr/lib/python3/dist-packages/urllib3/connectionpool.py", line 665, in urlopen
[2020-07-18 12:29:08,403] {bash_operator.py:126} INFO -     httplib_response = self._make_request(
[2020-07-18 12:29:08,403] {bash_operator.py:126} INFO -   File "/usr/lib/python3/dist-packages/urllib3/connectionpool.py", line 387, in _make_request
[2020-07-18 12:29:08,403] {bash_operator.py:126} INFO -     conn.request(method, url, **httplib_request_kw)
[2020-07-18 12:29:08,403] {bash_operator.py:126} INFO -   File "/usr/lib/python3.8/http/client.py", line 1240, in request
[2020-07-18 12:29:08,403] {bash_operator.py:126} INFO -     self._send_request(method, url, body, headers, encode_chunked)
[2020-07-18 12:29:08,404] {bash_operator.py:126} INFO -   File "/usr/lib/python3.8/http/client.py", line 1286, in _send_request
[2020-07-18 12:29:08,404] {bash_operator.py:126} INFO -     self.endheaders(body, encode_chunked=encode_chunked)
[2020-07-18 12:29:08,404] {bash_operator.py:126} INFO -   File "/usr/lib/python3.8/http/client.py", line 1235, in endheaders
[2020-07-18 12:29:08,404] {bash_operator.py:126} INFO -     self._send_output(message_body, encode_chunked=encode_chunked)
[2020-07-18 12:29:08,404] {bash_operator.py:126} INFO -   File "/usr/lib/python3.8/http/client.py", line 1006, in _send_output
[2020-07-18 12:29:08,404] {bash_operator.py:126} INFO -     self.send(msg)
[2020-07-18 12:29:08,404] {bash_operator.py:126} INFO -   File "/usr/lib/python3.8/http/client.py", line 946, in send
[2020-07-18 12:29:08,404] {bash_operator.py:126} INFO -     self.connect()
[2020-07-18 12:29:08,404] {bash_operator.py:126} INFO -   File "/usr/lib/python3/dist-packages/urllib3/connection.py", line 184, in connect
[2020-07-18 12:29:08,404] {bash_operator.py:126} INFO -     conn = self._new_conn()
[2020-07-18 12:29:08,404] {bash_operator.py:126} INFO -   File "/usr/lib/python3/dist-packages/urllib3/connection.py", line 168, in _new_conn
[2020-07-18 12:29:08,405] {bash_operator.py:126} INFO -     raise NewConnectionError(
[2020-07-18 12:29:08,405] {bash_operator.py:126} INFO - urllib3.exceptions.NewConnectionError: <urllib3.connection.HTTPConnection object at 0x7f4501642bb0>: Failed to establish a new connection: [Errno 111] Connection refused
[2020-07-18 12:29:08,405] {bash_operator.py:126} INFO - 
[2020-07-18 12:29:08,405] {bash_operator.py:126} INFO - During handling of the above exception, another exception occurred:
[2020-07-18 12:29:08,405] {bash_operator.py:126} INFO - 
[2020-07-18 12:29:08,405] {bash_operator.py:126} INFO - Traceback (most recent call last):
[2020-07-18 12:29:08,405] {bash_operator.py:126} INFO -   File "/home/bhakti/airflow/minioconnect/minio_connection.py", line 20, in <module>
[2020-07-18 12:29:08,405] {bash_operator.py:126} INFO -     minioClient.fput_object('airflowbucket', 'mysqldump1', '/home/bhakti/airflow/input_data/dump_mysql_db.db')
[2020-07-18 12:29:08,405] {bash_operator.py:126} INFO -   File "/usr/local/lib/python3.8/dist-packages/minio/api.py", line 698, in fput_object
[2020-07-18 12:29:08,405] {bash_operator.py:126} INFO -     return self.put_object(bucket_name, object_name, file_data,
[2020-07-18 12:29:08,405] {bash_operator.py:126} INFO -   File "/usr/local/lib/python3.8/dist-packages/minio/api.py", line 969, in put_object
[2020-07-18 12:29:08,406] {bash_operator.py:126} INFO -     return self._do_put_object(bucket_name, object_name,
[2020-07-18 12:29:08,406] {bash_operator.py:126} INFO -   File "/usr/local/lib/python3.8/dist-packages/minio/api.py", line 1682, in _do_put_object
[2020-07-18 12:29:08,406] {bash_operator.py:126} INFO -     response = self._url_open(
[2020-07-18 12:29:08,406] {bash_operator.py:126} INFO -   File "/usr/local/lib/python3.8/dist-packages/minio/api.py", line 1984, in _url_open
[2020-07-18 12:29:08,406] {bash_operator.py:126} INFO -     region = self._get_bucket_region(bucket_name)
[2020-07-18 12:29:08,406] {bash_operator.py:126} INFO -   File "/usr/local/lib/python3.8/dist-packages/minio/api.py", line 1919, in _get_bucket_region
[2020-07-18 12:29:08,406] {bash_operator.py:126} INFO -     region = self._get_bucket_location(bucket_name)
[2020-07-18 12:29:08,407] {bash_operator.py:126} INFO -   File "/usr/local/lib/python3.8/dist-packages/minio/api.py", line 1948, in _get_bucket_location
[2020-07-18 12:29:08,407] {bash_operator.py:126} INFO -     response = self._http.urlopen(method, url,
[2020-07-18 12:29:08,407] {bash_operator.py:126} INFO -   File "/usr/lib/python3/dist-packages/urllib3/poolmanager.py", line 330, in urlopen
[2020-07-18 12:29:08,407] {bash_operator.py:126} INFO -     response = conn.urlopen(method, u.request_uri, **kw)
[2020-07-18 12:29:08,407] {bash_operator.py:126} INFO -   File "/usr/lib/python3/dist-packages/urllib3/connectionpool.py", line 747, in urlopen
[2020-07-18 12:29:08,407] {bash_operator.py:126} INFO -     return self.urlopen(
[2020-07-18 12:29:08,407] {bash_operator.py:126} INFO -   File "/usr/lib/python3/dist-packages/urllib3/connectionpool.py", line 747, in urlopen
[2020-07-18 12:29:08,407] {bash_operator.py:126} INFO -     return self.urlopen(
[2020-07-18 12:29:08,408] {bash_operator.py:126} INFO -   File "/usr/lib/python3/dist-packages/urllib3/connectionpool.py", line 747, in urlopen
[2020-07-18 12:29:08,408] {bash_operator.py:126} INFO -     return self.urlopen(
[2020-07-18 12:29:08,408] {bash_operator.py:126} INFO -   [Previous line repeated 2 more times]
[2020-07-18 12:29:08,408] {bash_operator.py:126} INFO -   File "/usr/lib/python3/dist-packages/urllib3/connectionpool.py", line 719, in urlopen
[2020-07-18 12:29:08,408] {bash_operator.py:126} INFO -     retries = retries.increment(
[2020-07-18 12:29:08,408] {bash_operator.py:126} INFO -   File "/usr/lib/python3/dist-packages/urllib3/util/retry.py", line 436, in increment
[2020-07-18 12:29:08,408] {bash_operator.py:126} INFO -     raise MaxRetryError(_pool, url, error or ResponseError(cause))
[2020-07-18 12:29:08,408] {bash_operator.py:126} INFO - urllib3.exceptions.MaxRetryError: HTTPConnectionPool(host='localhost', port=9000): Max retries exceeded with url: /airflowbucket?location= (Caused by NewConnectionError('<urllib3.connection.HTTPConnection object at 0x7f4501642bb0>: Failed to establish a new connection: [Errno 111] Connection refused'))
[2020-07-18 12:29:08,557] {bash_operator.py:128} INFO - Command exited with return code 1
[2020-07-18 12:29:08,565] {taskinstance.py:1145} ERROR - Bash command failed
Traceback (most recent call last):
  File "/usr/local/lib/python3.8/dist-packages/airflow/models/taskinstance.py", line 983, in _run_raw_task
    result = task_copy.execute(context=context)
  File "/usr/local/lib/python3.8/dist-packages/airflow/operators/bash_operator.py", line 134, in execute
    raise AirflowException("Bash command failed")
airflow.exceptions.AirflowException: Bash command failed
[2020-07-18 12:29:08,568] {taskinstance.py:1174} INFO - All retries failed; marking task as FAILED.dag_id=storing_data, task_id=mysql_status, execution_date=20200718T065705, start_date=20200718T065900, end_date=20200718T065908
[2020-07-18 12:29:09,935] {logging_mixin.py:112} INFO - [2020-07-18 12:29:09,934] {local_task_job.py:103} INFO - Task exited with return code 1
