[2020-07-13 17:03:05,545] {taskinstance.py:669} INFO - Dependencies all met for <TaskInstance: employees_dag.check_file_exists 2020-07-13T11:31:28.319085+00:00 [queued]>
[2020-07-13 17:03:05,553] {taskinstance.py:669} INFO - Dependencies all met for <TaskInstance: employees_dag.check_file_exists 2020-07-13T11:31:28.319085+00:00 [queued]>
[2020-07-13 17:03:05,554] {taskinstance.py:879} INFO - 
--------------------------------------------------------------------------------
[2020-07-13 17:03:05,554] {taskinstance.py:880} INFO - Starting attempt 2 of 3
[2020-07-13 17:03:05,554] {taskinstance.py:881} INFO - 
--------------------------------------------------------------------------------
[2020-07-13 17:03:05,684] {taskinstance.py:900} INFO - Executing <Task(BashOperator): check_file_exists> on 2020-07-13T11:31:28.319085+00:00
[2020-07-13 17:03:05,689] {standard_task_runner.py:53} INFO - Started process 30385 to run task
[2020-07-13 17:03:05,862] {logging_mixin.py:112} INFO - Running %s on host %s <TaskInstance: employees_dag.check_file_exists 2020-07-13T11:31:28.319085+00:00 [running]> bhakti-Vostro-3558
[2020-07-13 17:03:05,876] {bash_operator.py:82} INFO - Tmp dir root location: 
 /tmp
[2020-07-13 17:03:05,877] {bash_operator.py:103} INFO - Temporary script location: /tmp/airflowtmpikrrzi7d/check_file_exists1xo3xuur
[2020-07-13 17:03:05,877] {bash_operator.py:115} INFO - Running command: python3 /home/bhakti/airflow/input_data/sample.csv
[2020-07-13 17:03:05,883] {bash_operator.py:122} INFO - Output:
[2020-07-13 17:03:06,002] {bash_operator.py:126} INFO - Traceback (most recent call last):
[2020-07-13 17:03:06,002] {bash_operator.py:126} INFO -   File "/home/bhakti/airflow/input_data/sample.csv", line 1, in <module>
[2020-07-13 17:03:06,002] {bash_operator.py:126} INFO -     PERSON,JOINING_YEAR,COMPANY
[2020-07-13 17:03:06,003] {bash_operator.py:126} INFO - NameError: name 'PERSON' is not defined
[2020-07-13 17:03:06,017] {bash_operator.py:128} INFO - Command exited with return code 1
[2020-07-13 17:03:06,024] {taskinstance.py:1145} ERROR - Bash command failed
Traceback (most recent call last):
  File "/usr/local/lib/python3.8/dist-packages/airflow/models/taskinstance.py", line 983, in _run_raw_task
    result = task_copy.execute(context=context)
  File "/usr/local/lib/python3.8/dist-packages/airflow/operators/bash_operator.py", line 134, in execute
    raise AirflowException("Bash command failed")
airflow.exceptions.AirflowException: Bash command failed
[2020-07-13 17:03:06,026] {taskinstance.py:1168} INFO - Marking task as UP_FOR_RETRY
[2020-07-13 17:03:15,423] {logging_mixin.py:112} INFO - [2020-07-13 17:03:15,423] {local_task_job.py:103} INFO - Task exited with return code 1
