[2020-08-26 11:51:17,757] {taskinstance.py:669} INFO - Dependencies all met for <TaskInstance: employees_dag.check_file_exists 2020-08-26T06:18:57.360228+00:00 [queued]>
[2020-08-26 11:51:17,767] {taskinstance.py:669} INFO - Dependencies all met for <TaskInstance: employees_dag.check_file_exists 2020-08-26T06:18:57.360228+00:00 [queued]>
[2020-08-26 11:51:17,768] {taskinstance.py:879} INFO - 
--------------------------------------------------------------------------------
[2020-08-26 11:51:17,768] {taskinstance.py:880} INFO - Starting attempt 1 of 3
[2020-08-26 11:51:17,768] {taskinstance.py:881} INFO - 
--------------------------------------------------------------------------------
[2020-08-26 11:51:17,973] {taskinstance.py:900} INFO - Executing <Task(BashOperator): check_file_exists> on 2020-08-26T06:18:57.360228+00:00
[2020-08-26 11:51:17,978] {standard_task_runner.py:53} INFO - Started process 76501 to run task
[2020-08-26 11:51:18,223] {logging_mixin.py:112} INFO - Running %s on host %s <TaskInstance: employees_dag.check_file_exists 2020-08-26T06:18:57.360228+00:00 [running]> bhakti-Vostro-3558
[2020-08-26 11:51:18,259] {bash_operator.py:82} INFO - Tmp dir root location: 
 /tmp
[2020-08-26 11:51:18,261] {bash_operator.py:103} INFO - Temporary script location: /tmp/airflowtmpl29po3vp/check_file_existsj2pbvchw
[2020-08-26 11:51:18,262] {bash_operator.py:115} INFO - Running command: shasum ~/input_files_airflow/sample.csv
[2020-08-26 11:51:18,273] {bash_operator.py:122} INFO - Output:
[2020-08-26 11:51:18,314] {bash_operator.py:126} INFO - shasum: /home/bhakti/input_files_airflow/sample.csv: No such file or directory
[2020-08-26 11:51:18,316] {bash_operator.py:128} INFO - Command exited with return code 1
[2020-08-26 11:51:18,325] {taskinstance.py:1145} ERROR - Bash command failed
Traceback (most recent call last):
  File "/usr/local/lib/python3.8/dist-packages/airflow/models/taskinstance.py", line 983, in _run_raw_task
    result = task_copy.execute(context=context)
  File "/usr/local/lib/python3.8/dist-packages/airflow/operators/bash_operator.py", line 134, in execute
    raise AirflowException("Bash command failed")
airflow.exceptions.AirflowException: Bash command failed
[2020-08-26 11:51:18,329] {taskinstance.py:1168} INFO - Marking task as UP_FOR_RETRY
[2020-08-26 11:51:27,615] {logging_mixin.py:112} INFO - [2020-08-26 11:51:27,614] {local_task_job.py:103} INFO - Task exited with return code 1
