[2020-07-16 14:34:44,032] {taskinstance.py:669} INFO - Dependencies all met for <TaskInstance: employees_dag.check_file_exists 2020-07-16T09:01:35.755358+00:00 [queued]>
[2020-07-16 14:34:44,042] {taskinstance.py:669} INFO - Dependencies all met for <TaskInstance: employees_dag.check_file_exists 2020-07-16T09:01:35.755358+00:00 [queued]>
[2020-07-16 14:34:44,042] {taskinstance.py:879} INFO - 
--------------------------------------------------------------------------------
[2020-07-16 14:34:44,042] {taskinstance.py:880} INFO - Starting attempt 3 of 3
[2020-07-16 14:34:44,042] {taskinstance.py:881} INFO - 
--------------------------------------------------------------------------------
[2020-07-16 14:34:44,291] {taskinstance.py:900} INFO - Executing <Task(BashOperator): check_file_exists> on 2020-07-16T09:01:35.755358+00:00
[2020-07-16 14:34:44,294] {standard_task_runner.py:53} INFO - Started process 502013 to run task
[2020-07-16 14:34:44,555] {logging_mixin.py:112} INFO - Running %s on host %s <TaskInstance: employees_dag.check_file_exists 2020-07-16T09:01:35.755358+00:00 [running]> bhakti-Vostro-3558
[2020-07-16 14:34:44,600] {bash_operator.py:82} INFO - Tmp dir root location: 
 /tmp
[2020-07-16 14:34:44,601] {bash_operator.py:103} INFO - Temporary script location: /tmp/airflowtmpi0k6kc2r/check_file_exists8hczf8kl
[2020-07-16 14:34:44,601] {bash_operator.py:115} INFO - Running command: shasum ~/input_files_airflow/sample.csv
[2020-07-16 14:34:44,636] {bash_operator.py:122} INFO - Output:
[2020-07-16 14:34:44,872] {bash_operator.py:126} INFO - shasum: /home/bhakti/input_files_airflow/sample.csv: No such file or directory
[2020-07-16 14:34:44,873] {bash_operator.py:128} INFO - Command exited with return code 1
[2020-07-16 14:34:44,889] {taskinstance.py:1145} ERROR - Bash command failed
Traceback (most recent call last):
  File "/usr/local/lib/python3.8/dist-packages/airflow/models/taskinstance.py", line 983, in _run_raw_task
    result = task_copy.execute(context=context)
  File "/usr/local/lib/python3.8/dist-packages/airflow/operators/bash_operator.py", line 134, in execute
    raise AirflowException("Bash command failed")
airflow.exceptions.AirflowException: Bash command failed
[2020-07-16 14:34:44,892] {taskinstance.py:1174} INFO - All retries failed; marking task as FAILED.dag_id=employees_dag, task_id=check_file_exists, execution_date=20200716T090135, start_date=20200716T090444, end_date=20200716T090444
[2020-07-16 14:34:53,442] {logging_mixin.py:112} INFO - [2020-07-16 14:34:53,442] {local_task_job.py:103} INFO - Task exited with return code 1
