[2020-08-26 12:04:20,341] {taskinstance.py:669} INFO - Dependencies all met for <TaskInstance: employees_dag.create_mysql_table 2020-08-26T06:23:01.721102+00:00 [queued]>
[2020-08-26 12:04:20,361] {taskinstance.py:669} INFO - Dependencies all met for <TaskInstance: employees_dag.create_mysql_table 2020-08-26T06:23:01.721102+00:00 [queued]>
[2020-08-26 12:04:20,361] {taskinstance.py:879} INFO - 
--------------------------------------------------------------------------------
[2020-08-26 12:04:20,361] {taskinstance.py:880} INFO - Starting attempt 2 of 2
[2020-08-26 12:04:20,361] {taskinstance.py:881} INFO - 
--------------------------------------------------------------------------------
[2020-08-26 12:04:20,570] {taskinstance.py:900} INFO - Executing <Task(MySqlOperator): create_mysql_table> on 2020-08-26T06:23:01.721102+00:00
[2020-08-26 12:04:20,574] {standard_task_runner.py:53} INFO - Started process 84236 to run task
[2020-08-26 12:04:20,973] {logging_mixin.py:112} INFO - Running %s on host %s <TaskInstance: employees_dag.create_mysql_table 2020-08-26T06:23:01.721102+00:00 [running]> bhakti-Vostro-3558
[2020-08-26 12:04:21,097] {mysql_operator.py:61} INFO - Executing: CREATE TABLE IF NOT EXISTS employees(PERSON TEXT,JOINING_YEAR BIGINT, COMPANY TEXT);
[2020-08-26 12:04:21,187] {logging_mixin.py:112} INFO - [2020-08-26 12:04:21,186] {base_hook.py:87} INFO - Using connection to: id: local_mysql. Host: 127.0.0.1, Port: 3306, Schema: sqoop_db, Login: sqoop_db, Password: XXXXXXXX, extra: None
[2020-08-26 12:04:21,191] {taskinstance.py:1145} ERROR - (1045, "Access denied for user 'sqoop_db'@'172.22.0.1' (using password: YES)")
Traceback (most recent call last):
  File "/usr/local/lib/python3.8/dist-packages/airflow/models/taskinstance.py", line 983, in _run_raw_task
    result = task_copy.execute(context=context)
  File "/usr/local/lib/python3.8/dist-packages/airflow/operators/mysql_operator.py", line 64, in execute
    hook.run(
  File "/usr/local/lib/python3.8/dist-packages/airflow/hooks/dbapi_hook.py", line 162, in run
    with closing(self.get_conn()) as conn:
  File "/usr/local/lib/python3.8/dist-packages/airflow/hooks/mysql_hook.py", line 116, in get_conn
    conn = MySQLdb.connect(**conn_config)
  File "/usr/local/lib/python3.8/dist-packages/pymysql/__init__.py", line 94, in Connect
    return Connection(*args, **kwargs)
  File "/usr/local/lib/python3.8/dist-packages/pymysql/connections.py", line 325, in __init__
    self.connect()
  File "/usr/local/lib/python3.8/dist-packages/pymysql/connections.py", line 599, in connect
    self._request_authentication()
  File "/usr/local/lib/python3.8/dist-packages/pymysql/connections.py", line 861, in _request_authentication
    auth_packet = self._read_packet()
  File "/usr/local/lib/python3.8/dist-packages/pymysql/connections.py", line 684, in _read_packet
    packet.check_error()
  File "/usr/local/lib/python3.8/dist-packages/pymysql/protocol.py", line 220, in check_error
    err.raise_mysql_exception(self._data)
  File "/usr/local/lib/python3.8/dist-packages/pymysql/err.py", line 109, in raise_mysql_exception
    raise errorclass(errno, errval)
pymysql.err.OperationalError: (1045, "Access denied for user 'sqoop_db'@'172.22.0.1' (using password: YES)")
[2020-08-26 12:04:21,195] {taskinstance.py:1174} INFO - All retries failed; marking task as FAILED.dag_id=employees_dag, task_id=create_mysql_table, execution_date=20200826T062301, start_date=20200826T063420, end_date=20200826T063421
[2020-08-26 12:04:30,198] {logging_mixin.py:112} INFO - [2020-08-26 12:04:30,198] {local_task_job.py:103} INFO - Task exited with return code 1
