[2020-07-13 09:02:50,127] {taskinstance.py:669} INFO - Dependencies all met for <TaskInstance: employees_dag.insert_mysql_table 2020-07-13T03:31:06.847998+00:00 [queued]>
[2020-07-13 09:02:50,142] {taskinstance.py:669} INFO - Dependencies all met for <TaskInstance: employees_dag.insert_mysql_table 2020-07-13T03:31:06.847998+00:00 [queued]>
[2020-07-13 09:02:50,142] {taskinstance.py:879} INFO - 
--------------------------------------------------------------------------------
[2020-07-13 09:02:50,142] {taskinstance.py:880} INFO - Starting attempt 1 of 2
[2020-07-13 09:02:50,142] {taskinstance.py:881} INFO - 
--------------------------------------------------------------------------------
[2020-07-13 09:02:50,261] {taskinstance.py:900} INFO - Executing <Task(MySqlOperator): insert_mysql_table> on 2020-07-13T03:31:06.847998+00:00
[2020-07-13 09:02:50,265] {standard_task_runner.py:53} INFO - Started process 9989 to run task
[2020-07-13 09:02:50,485] {logging_mixin.py:112} INFO - Running %s on host %s <TaskInstance: employees_dag.insert_mysql_table 2020-07-13T03:31:06.847998+00:00 [running]> bhakti-Vostro-3558
[2020-07-13 09:02:50,502] {mysql_operator.py:61} INFO - Executing: LOAD DATA INFILE '/home/bhakti/airflow/input_data/sample.csv' INTO TABLE employees_data FIELDS TERMINATED BY ','
LINES TERMINATED BY '\n' IGNORE 1 ROWS;
[2020-07-13 09:02:50,563] {logging_mixin.py:112} INFO - [2020-07-13 09:02:50,562] {base_hook.py:87} INFO - Using connection to: id: mysql_conn. Host: mysql, Port: None, Schema: mysql, Login: root, Password: XXXXXXXX, extra: None
[2020-07-13 09:02:50,566] {taskinstance.py:1145} ERROR - (2003, "Can't connect to MySQL server on 'mysql' ([Errno -3] Temporary failure in name resolution)")
Traceback (most recent call last):
  File "/usr/local/lib/python3.8/dist-packages/pymysql/connections.py", line 581, in connect
    sock = socket.create_connection(
  File "/usr/lib/python3.8/socket.py", line 787, in create_connection
    for res in getaddrinfo(host, port, 0, SOCK_STREAM):
  File "/usr/lib/python3.8/socket.py", line 918, in getaddrinfo
    for res in _socket.getaddrinfo(host, port, family, type, proto, flags):
socket.gaierror: [Errno -3] Temporary failure in name resolution

During handling of the above exception, another exception occurred:

Traceback (most recent call last):
  File "/usr/local/lib/python3.8/dist-packages/airflow/models/taskinstance.py", line 983, in _run_raw_task
    result = task_copy.execute(context=context)
  File "/usr/local/lib/python3.8/dist-packages/airflow/operators/mysql_operator.py", line 64, in execute
    hook.run(
  File "/usr/local/lib/python3.8/dist-packages/airflow/hooks/dbapi_hook.py", line 162, in run
    with closing(self.get_conn()) as conn:
  File "/usr/local/lib/python3.8/dist-packages/airflow/hooks/mysql_hook.py", line 116, in get_conn
    conn = MySQLdb.connect(**conn_config)
  File "/usr/local/lib/python3.8/dist-packages/pymysql/__init__.py", line 94, in Connect
    return Connection(*args, **kwargs)
  File "/usr/local/lib/python3.8/dist-packages/pymysql/connections.py", line 325, in __init__
    self.connect()
  File "/usr/local/lib/python3.8/dist-packages/pymysql/connections.py", line 630, in connect
    raise exc
pymysql.err.OperationalError: (2003, "Can't connect to MySQL server on 'mysql' ([Errno -3] Temporary failure in name resolution)")
[2020-07-13 09:02:50,567] {taskinstance.py:1168} INFO - Marking task as UP_FOR_RETRY
[2020-07-13 09:02:59,969] {logging_mixin.py:112} INFO - [2020-07-13 09:02:59,968] {local_task_job.py:103} INFO - Task exited with return code 1
