[2020-07-10 16:20:57,423] {taskinstance.py:669} INFO - Dependencies all met for <TaskInstance: CSVDAG.status 2020-07-10T10:49:00.872894+00:00 [queued]>
[2020-07-10 16:20:57,435] {taskinstance.py:669} INFO - Dependencies all met for <TaskInstance: CSVDAG.status 2020-07-10T10:49:00.872894+00:00 [queued]>
[2020-07-10 16:20:57,435] {taskinstance.py:879} INFO - 
--------------------------------------------------------------------------------
[2020-07-10 16:20:57,435] {taskinstance.py:880} INFO - Starting attempt 1 of 2
[2020-07-10 16:20:57,435] {taskinstance.py:881} INFO - 
--------------------------------------------------------------------------------
[2020-07-10 16:20:57,569] {taskinstance.py:900} INFO - Executing <Task(PythonOperator): status> on 2020-07-10T10:49:00.872894+00:00
[2020-07-10 16:20:57,576] {standard_task_runner.py:53} INFO - Started process 65088 to run task
[2020-07-10 16:20:57,909] {logging_mixin.py:112} INFO - Running %s on host %s <TaskInstance: CSVDAG.status 2020-07-10T10:49:00.872894+00:00 [running]> bhakti-Vostro-3558
[2020-07-10 16:20:57,984] {taskinstance.py:1145} ERROR - success_of_status() got an unexpected keyword argument 'conf'
Traceback (most recent call last):
  File "/usr/local/lib/python3.8/dist-packages/airflow/models/taskinstance.py", line 983, in _run_raw_task
    result = task_copy.execute(context=context)
  File "/usr/local/lib/python3.8/dist-packages/airflow/operators/python_operator.py", line 113, in execute
    return_value = self.execute_callable()
  File "/usr/local/lib/python3.8/dist-packages/airflow/operators/python_operator.py", line 118, in execute_callable
    return self.python_callable(*self.op_args, **self.op_kwargs)
TypeError: success_of_status() got an unexpected keyword argument 'conf'
[2020-07-10 16:20:57,986] {taskinstance.py:1168} INFO - Marking task as UP_FOR_RETRY
[2020-07-10 16:21:07,286] {logging_mixin.py:112} INFO - [2020-07-10 16:21:07,285] {local_task_job.py:103} INFO - Task exited with return code 1
