[2020-07-13 17:06:13,761] {taskinstance.py:669} INFO - Dependencies all met for <TaskInstance: employees_dag.check_file_exists 2020-07-13T11:35:51.903068+00:00 [queued]>
[2020-07-13 17:06:13,774] {taskinstance.py:669} INFO - Dependencies all met for <TaskInstance: employees_dag.check_file_exists 2020-07-13T11:35:51.903068+00:00 [queued]>
[2020-07-13 17:06:13,775] {taskinstance.py:879} INFO - 
--------------------------------------------------------------------------------
[2020-07-13 17:06:13,775] {taskinstance.py:880} INFO - Starting attempt 1 of 3
[2020-07-13 17:06:13,775] {taskinstance.py:881} INFO - 
--------------------------------------------------------------------------------
[2020-07-13 17:06:13,898] {taskinstance.py:900} INFO - Executing <Task(BashOperator): check_file_exists> on 2020-07-13T11:35:51.903068+00:00
[2020-07-13 17:06:13,901] {standard_task_runner.py:53} INFO - Started process 30650 to run task
[2020-07-13 17:06:14,106] {logging_mixin.py:112} INFO - Running %s on host %s <TaskInstance: employees_dag.check_file_exists 2020-07-13T11:35:51.903068+00:00 [running]> bhakti-Vostro-3558
[2020-07-13 17:06:14,123] {bash_operator.py:82} INFO - Tmp dir root location: 
 /tmp
[2020-07-13 17:06:14,123] {bash_operator.py:103} INFO - Temporary script location: /tmp/airflowtmpa54_pl41/check_file_existsh6652y2p
[2020-07-13 17:06:14,124] {bash_operator.py:115} INFO - Running command: python3 /home/bhakti/airflow/input_data/sample.csv
[2020-07-13 17:06:14,130] {bash_operator.py:122} INFO - Output:
[2020-07-13 17:06:14,303] {bash_operator.py:126} INFO - Traceback (most recent call last):
[2020-07-13 17:06:14,304] {bash_operator.py:126} INFO -   File "/home/bhakti/airflow/input_data/sample.csv", line 1, in <module>
[2020-07-13 17:06:14,304] {bash_operator.py:126} INFO -     PERSON,JOINING_YEAR,COMPANY
[2020-07-13 17:06:14,304] {bash_operator.py:126} INFO - NameError: name 'PERSON' is not defined
[2020-07-13 17:06:14,333] {bash_operator.py:128} INFO - Command exited with return code 1
[2020-07-13 17:06:14,345] {taskinstance.py:1145} ERROR - Bash command failed
Traceback (most recent call last):
  File "/usr/local/lib/python3.8/dist-packages/airflow/models/taskinstance.py", line 983, in _run_raw_task
    result = task_copy.execute(context=context)
  File "/usr/local/lib/python3.8/dist-packages/airflow/operators/bash_operator.py", line 134, in execute
    raise AirflowException("Bash command failed")
airflow.exceptions.AirflowException: Bash command failed
[2020-07-13 17:06:14,348] {taskinstance.py:1168} INFO - Marking task as UP_FOR_RETRY
[2020-07-13 17:06:23,636] {logging_mixin.py:112} INFO - [2020-07-13 17:06:23,635] {local_task_job.py:103} INFO - Task exited with return code 1
